...started at Thu Jun 10 15:14:48 EDT 2021

======================================
  MutSigCV
  v1.4

  (c) Mike Lawrence and Gaddy Getz
  Broad Institute of MIT and Harvard
======================================


MutSigCV: PREPROCESS
--------------------
Loading mutation_file...
Loading coverage file...
Processing mutation "effect"...
WARNING:  80/1402 mutations could not be mapped to effect using mutation_type_dictionary_file:

      lincRNA: [80]
    ----TOTAL: [80]
          They will be removed from the analysis.
Processing mutation "categ"...
Will use the categories already present.
Writing preprocessed files.
MutSig_preprocess finished.


MutSigCV: RUN
-------------
Loading mutation_file...
NOTE:  Both "gene" and "Hugo_Symbol" are present in mutation_file.  Using "gene".
NOTE:  Both "patient" and "Tumor_Sample_Barcode" are present in mutation_file.  Using "patient".
Loading coverage file...
Loading covariate file...
NOTE:  66/538 gene names could not be mapped to coverage information.  Excluding them.
NOTE:  Converting "-" to "_" in patient names.

cellContents =

    'fc93e38d6bd59912e04011ac0c4838cd'


cellContents =

    'fc9469d04d0ebb59e04011ac0d481e59'


cellContents =

    'fc998aec57ddeab2e04011ac0d48680a'


cellContents =

    'fc99b7347f6188d1e04011ac0c482e88'


cellContents =

    'fc99bbb0e5c7fb9ee04011ac0d4807e1'

Building n and N tables...
Error using MutSigCV_nbg>MutSig_runCV (line 865)
not enough mutations to analyze

Error in MutSigCV_nbg (line 194)
  MutSig_runCV(mutation_file,coverage_file,covariate_file,output_file);

Bone-Osteoblast
Traceback (most recent call last):
  File "run_histology_nsyn.py", line 37, in <module>
    runMutSigCV_nsyn(feat)
  File "run_histology_nsyn.py", line 34, in runMutSigCV_nsyn
    eng.MutSigCV_nbg(maf,cov, covariates, outp, mut_dic, chain_f, nargout = 0)
  File "/storage/home/yur97/.local/lib/python3.6/site-packages/matlab/engine/matlabengine.py", line 71, in __call__
    _stderr, feval=True).result()
  File "/storage/home/yur97/.local/lib/python3.6/site-packages/matlab/engine/futureresult.py", line 67, in result
    return self.__future.result(timeout)
  File "/storage/home/yur97/.local/lib/python3.6/site-packages/matlab/engine/fevalfuture.py", line 82, in result
    self._result = pythonengine.getFEvalResult(self._future,self._nargout, None, out=self._out, err=self._err)
matlab.engine.MatlabExecutionError: 
  File /gpfs/group/epo2/default/yur97/gitlab/pcawg-to-mutsigcv/mutsig/MutSigCV_nbg.m, line 865, in MutSig_runCV

  File /gpfs/group/epo2/default/yur97/gitlab/pcawg-to-mutsigcv/mutsig/MutSigCV_nbg.m, line 194, in MutSigCV_nbg
not enough mutations to analyze

...ended at Thu Jun 10 15:15:37 EDT 2021
